2021-06-25 11:21:42,444 - create_public - ERROR - Error detected
Traceback (most recent call last):
  File "C:\Users\Webdom16\PycharmProjects\TestsCovid\COVID_19_ 9880\Cоздание_исследований\create_public.py", line 32, in genlog
    self.create_public()
  File "C:\Users\Webdom16\PycharmProjects\TestsCovid\COVID_19_ 9880\Cоздание_исследований\create_public.py", line 74, in create_public
    driver.find_element_by_name("Region").send_keys(u"РЎР°РЅРєС‚-РџРµС‚РµСЂР±СѓСЂРі").click()
AttributeError: 'NoneType' object has no attribute 'click'
