2021-06-25 11:26:14,786 - create_public - ERROR - Error detected
Traceback (most recent call last):
  File "C:\Users\Webdom16\PycharmProjects\TestsCovid\COVID_19_ 9880\Cоздание_исследований\create_public.py", line 32, in genlog
    self.create_public()
  File "C:\Users\Webdom16\PycharmProjects\TestsCovid\COVID_19_ 9880\Cоздание_исследований\create_public.py", line 69, in create_public
    if option.text == u"РђР±С…Р°Р·РёСЏ":
  File "C:\Python27\lib\site-packages\selenium\webdriver\remote\webelement.py", line 76, in text
    return self._execute(Command.GET_ELEMENT_TEXT)['value']
  File "C:\Python27\lib\site-packages\selenium\webdriver\remote\webelement.py", line 633, in _execute
    return self._parent.execute(command, params)
  File "C:\Python27\lib\site-packages\selenium\webdriver\remote\webdriver.py", line 321, in execute
    self.error_handler.check_response(response)
  File "C:\Python27\lib\site-packages\selenium\webdriver\remote\errorhandler.py", line 242, in check_response
    raise exception_class(message, screen, stacktrace)
WebDriverException: Message: chrome not reachable
  (Session info: chrome=91.0.4472.114)

2021-06-25 11:26:35,125 - create_public - ERROR - Error detected
Traceback (most recent call last):
  File "C:\Users\Webdom16\PycharmProjects\TestsCovid\COVID_19_ 9880\Cоздание_исследований\create_public.py", line 32, in genlog
    self.create_public()
  File "C:\Users\Webdom16\PycharmProjects\TestsCovid\COVID_19_ 9880\Cоздание_исследований\create_public.py", line 69, in create_public
    if option.text == u"РђР±С…Р°Р·РёСЏ":
  File "C:\Python27\lib\site-packages\selenium\webdriver\remote\webelement.py", line 76, in text
    return self._execute(Command.GET_ELEMENT_TEXT)['value']
  File "C:\Python27\lib\site-packages\selenium\webdriver\remote\webelement.py", line 633, in _execute
    return self._parent.execute(command, params)
  File "C:\Python27\lib\site-packages\selenium\webdriver\remote\webdriver.py", line 321, in execute
    self.error_handler.check_response(response)
  File "C:\Python27\lib\site-packages\selenium\webdriver\remote\errorhandler.py", line 242, in check_response
    raise exception_class(message, screen, stacktrace)
WebDriverException: Message: chrome not reachable
  (Session info: chrome=91.0.4472.114)

