2021-06-28 11:44:02,638 - create_Antitel - ERROR - Error detected
Traceback (most recent call last):
  File "C:\Users\Webdom16\PycharmProjects\TestsCovid\COVID_19_ 9880\Cоздание_исследований\create_Antitel.py", line 31, in genlog
    self.create_antitel()
  File "C:\Users\Webdom16\PycharmProjects\TestsCovid\COVID_19_ 9880\Cоздание_исследований\create_Antitel.py", line 42, in create_antitel
    driver.get("http://auraep.ru:9880/business/dashboard/dashboard.xhtml")
  File "C:\Python27\lib\site-packages\selenium\webdriver\remote\webdriver.py", line 333, in get
    self.execute(Command.GET, {'url': url})
  File "C:\Python27\lib\site-packages\selenium\webdriver\remote\webdriver.py", line 321, in execute
    self.error_handler.check_response(response)
  File "C:\Python27\lib\site-packages\selenium\webdriver\remote\errorhandler.py", line 242, in check_response
    raise exception_class(message, screen, stacktrace)
WebDriverException: Message: unknown error: net::ERR_CONNECTION_REFUSED
  (Session info: chrome=91.0.4472.114)

