2021-06-01 16:39:40,358 - __main__ - INFO - Error detected
Traceback (most recent call last):
  File "C:\Work\Работа\Питон\COVID_19_ 9880\Cоздание_исследований\create_PCR.py", line 29, in genlog
    self.create_pcr()
  File "C:\Work\Работа\Питон\COVID_19_ 9880\Cоздание_исследований\create_PCR.py", line 173, in create_pcr
    window_after = driver.window_handles[1]
IndexError: list index out of range
