2021-06-25 11:13:13,440 - create_public - ERROR - Error detected
Traceback (most recent call last):
  File "C:\Users\Webdom16\PycharmProjects\TestsCovid\COVID_19_ 9880\Cоздание_исследований\create_public.py", line 32, in genlog
    self.create_public()
  File "C:\Users\Webdom16\PycharmProjects\TestsCovid\COVID_19_ 9880\Cоздание_исследований\create_public.py", line 66, in create_public
    select=Select(driver.find_element_by_name("Strana").click())
  File "C:\Python27\lib\site-packages\selenium\webdriver\support\select.py", line 36, in __init__
    if webelement.tag_name.lower() != "select":
AttributeError: 'NoneType' object has no attribute 'tag_name'
2021-06-25 11:13:48,240 - create_public - ERROR - Error detected
Traceback (most recent call last):
  File "C:\Users\Webdom16\PycharmProjects\TestsCovid\COVID_19_ 9880\Cоздание_исследований\create_public.py", line 32, in genlog
    self.create_public()
  File "C:\Users\Webdom16\PycharmProjects\TestsCovid\COVID_19_ 9880\Cоздание_исследований\create_public.py", line 69, in create_public
    select.select_by_value('1')
  File "C:\Python27\lib\site-packages\selenium\webdriver\support\select.py", line 81, in select_by_value
    for opt in opts:
TypeError: 'NoneType' object is not iterable
