2021-06-25 11:49:45,950 - create_public - ERROR - Error detected
Traceback (most recent call last):
  File "C:\Users\Webdom16\PycharmProjects\TestsCovid\COVID_19_ 9880\Cоздание_исследований\create_public.py", line 37, in genlog
    self.create_public()
  File "C:\Users\Webdom16\PycharmProjects\TestsCovid\COVID_19_ 9880\Cоздание_исследований\create_public.py", line 83, in create_public
    driver.find_element_by_name("Region").click()
  File "C:\Python27\lib\site-packages\selenium\webdriver\remote\webdriver.py", line 496, in find_element_by_name
    return self.find_element(by=By.NAME, value=name)
  File "C:\Python27\lib\site-packages\selenium\webdriver\remote\webdriver.py", line 978, in find_element
    'value': value})['value']
  File "C:\Python27\lib\site-packages\selenium\webdriver\remote\webdriver.py", line 321, in execute
    self.error_handler.check_response(response)
  File "C:\Python27\lib\site-packages\selenium\webdriver\remote\errorhandler.py", line 242, in check_response
    raise exception_class(message, screen, stacktrace)
WebDriverException: Message: chrome not reachable
  (Session info: chrome=91.0.4472.114)

