2021-06-28 11:52:15,618 - create_public - ERROR - Error detected
Traceback (most recent call last):
  File "C:\Users\Webdom16\PycharmProjects\TestsCovid\COVID_19_ 9880\Cоздание_исследований\create_public.py", line 37, in genlog
    self.create_public()
  File "C:\Users\Webdom16\PycharmProjects\TestsCovid\COVID_19_ 9880\Cоздание_исследований\create_public.py", line 83, in create_public
    select = Select(driver.find_element_by_id("city"))
  File "C:\Python27\lib\site-packages\selenium\webdriver\support\select.py", line 39, in __init__
    webelement.tag_name)
UnexpectedTagNameException: Message: Select only works on <select> elements, not on <input>

2021-06-28 11:52:33,813 - create_public - ERROR - Error detected
Traceback (most recent call last):
  File "C:\Users\Webdom16\PycharmProjects\TestsCovid\COVID_19_ 9880\Cоздание_исследований\create_public.py", line 37, in genlog
    self.create_public()
  File "C:\Users\Webdom16\PycharmProjects\TestsCovid\COVID_19_ 9880\Cоздание_исследований\create_public.py", line 83, in create_public
    select = Select(driver.find_element_by_id("city"))
  File "C:\Python27\lib\site-packages\selenium\webdriver\support\select.py", line 39, in __init__
    webelement.tag_name)
UnexpectedTagNameException: Message: Select only works on <select> elements, not on <input>

2021-06-28 11:52:52,321 - create_public - ERROR - Error detected
Traceback (most recent call last):
  File "C:\Users\Webdom16\PycharmProjects\TestsCovid\COVID_19_ 9880\Cоздание_исследований\create_public.py", line 37, in genlog
    self.create_public()
  File "C:\Users\Webdom16\PycharmProjects\TestsCovid\COVID_19_ 9880\Cоздание_исследований\create_public.py", line 83, in create_public
    select = Select(driver.find_element_by_id("city"))
  File "C:\Python27\lib\site-packages\selenium\webdriver\support\select.py", line 39, in __init__
    webelement.tag_name)
UnexpectedTagNameException: Message: Select only works on <select> elements, not on <input>

