2021-05-13 00:00:29,255 - __main__ - INFO - Error detected
Traceback (most recent call last):
  File "F:\Музыка\!Work Webdom\!Тесты_питон\COVID_19_ 9880\Заполнение_лабораторных_планшетов\lab_planshet_1.py", line 29, in genlog
    self.lab_planshet()
  File "F:\Музыка\!Work Webdom\!Тесты_питон\COVID_19_ 9880\Заполнение_лабораторных_планшетов\lab_planshet_1.py", line 65, in lab_planshet
    assert driver.find_element_by_css_selector("#tabletForm\:tube_1_7_content > span.content-value").text == iss1
  File "C:\Users\Dangel\AppData\Local\Programs\Python\Python39\lib\site-packages\selenium\webdriver\remote\webdriver.py", line 598, in find_element_by_css_selector
    return self.find_element(by=By.CSS_SELECTOR, value=css_selector)
  File "C:\Users\Dangel\AppData\Local\Programs\Python\Python39\lib\site-packages\selenium\webdriver\remote\webdriver.py", line 976, in find_element
    return self.execute(Command.FIND_ELEMENT, {
  File "C:\Users\Dangel\AppData\Local\Programs\Python\Python39\lib\site-packages\selenium\webdriver\remote\webdriver.py", line 321, in execute
    self.error_handler.check_response(response)
  File "C:\Users\Dangel\AppData\Local\Programs\Python\Python39\lib\site-packages\selenium\webdriver\remote\errorhandler.py", line 242, in check_response
    raise exception_class(message, screen, stacktrace)
selenium.common.exceptions.WebDriverException: Message: chrome not reachable
  (Session info: chrome=90.0.4430.93)

