2021-06-01 16:48:55,750 - __main__ - INFO - Error detected
Traceback (most recent call last):
  File "C:\Work\Работа\Питон\COVID_19_ 9880\Cоздание_исследований\create_PCR.py", line 29, in genlog
    self.create_pcr()
  File "C:\Work\Работа\Питон\COVID_19_ 9880\Cоздание_исследований\create_PCR.py", line 50, in create_pcr
    driver.find_element_by_css_selector("#buttonsForm\:createPcr").click()
  File "C:\Python27\lib\site-packages\selenium\webdriver\remote\webdriver.py", line 598, in find_element_by_css_selector
    return self.find_element(by=By.CSS_SELECTOR, value=css_selector)
  File "C:\Python27\lib\site-packages\selenium\webdriver\remote\webdriver.py", line 978, in find_element
    'value': value})['value']
  File "C:\Python27\lib\site-packages\selenium\webdriver\remote\webdriver.py", line 321, in execute
    self.error_handler.check_response(response)
  File "C:\Python27\lib\site-packages\selenium\webdriver\remote\errorhandler.py", line 242, in check_response
    raise exception_class(message, screen, stacktrace)
WebDriverException: Message: chrome not reachable
  (Session info: chrome=90.0.4430.212)

