2021-06-24 18:37:26,726 - create_PCR - ERROR - Error detected
Traceback (most recent call last):
  File "C:\Users\Webdom16\PycharmProjects\TestsCovid\COVID_19_ 9880\Cоздание_исследований\create_PCR.py", line 31, in genlog
    self.create_pcr()
  File "C:\Users\Webdom16\PycharmProjects\TestsCovid\COVID_19_ 9880\Cоздание_исследований\create_PCR.py", line 180, in create_pcr
    window_after = driver.window_handles[1]
IndexError: list index out of range
